Traceback (most recent call last):
  File "/home/frederikwr/anaconda3/envs/WindBro/lib/python3.11/site-packages/jupyter_cache/executors/utils.py", line 58, in single_nb_execution
    executenb(
  File "/home/frederikwr/anaconda3/envs/WindBro/lib/python3.11/site-packages/nbclient/client.py", line 1204, in execute
    return NotebookClient(nb=nb, resources=resources, km=km, **kwargs).execute()
           ^^^^^^^^^^^^^^^^^^^^^^^^^^^^^^^^^^^^^^^^^^^^^^^^^^^^^^^^^^^^^^^^^^^^^
  File "/home/frederikwr/anaconda3/envs/WindBro/lib/python3.11/site-packages/nbclient/util.py", line 84, in wrapped
    return just_run(coro(*args, **kwargs))
           ^^^^^^^^^^^^^^^^^^^^^^^^^^^^^^^
  File "/home/frederikwr/anaconda3/envs/WindBro/lib/python3.11/site-packages/nbclient/util.py", line 62, in just_run
    return loop.run_until_complete(coro)
           ^^^^^^^^^^^^^^^^^^^^^^^^^^^^^
  File "/home/frederikwr/anaconda3/envs/WindBro/lib/python3.11/asyncio/base_events.py", line 653, in run_until_complete
    return future.result()
           ^^^^^^^^^^^^^^^
  File "/home/frederikwr/anaconda3/envs/WindBro/lib/python3.11/site-packages/nbclient/client.py", line 663, in async_execute
    await self.async_execute_cell(
  File "/home/frederikwr/anaconda3/envs/WindBro/lib/python3.11/site-packages/nbclient/client.py", line 965, in async_execute_cell
    await self._check_raise_for_error(cell, cell_index, exec_reply)
  File "/home/frederikwr/anaconda3/envs/WindBro/lib/python3.11/site-packages/nbclient/client.py", line 862, in _check_raise_for_error
    raise CellExecutionError.from_cell_and_msg(cell, exec_reply_content)
nbclient.exceptions.CellExecutionError: An error occurred while executing the following cell:
------------------
from cython import solve_shadow_map
import multiprocessing as mp
import pandas as pd
import matplotlib.pyplot as plt
from matplotlib.colors import LogNorm
import numpy as np
from utils import solar_angles_to_vector, solar_position, rotor_point_spacing, generate_turbine, generate_voxel_map
------------------

[0;31m---------------------------------------------------------------------------[0m
[0;31mImportError[0m                               Traceback (most recent call last)
Cell [0;32mIn[1], line 1[0m
[0;32m----> 1[0m [38;5;28;01mfrom[39;00m [38;5;21;01mcython[39;00m [38;5;28;01mimport[39;00m solve_shadow_map
[1;32m      2[0m [38;5;28;01mimport[39;00m [38;5;21;01mmultiprocessing[39;00m [38;5;28;01mas[39;00m [38;5;21;01mmp[39;00m
[1;32m      3[0m [38;5;28;01mimport[39;00m [38;5;21;01mpandas[39;00m [38;5;28;01mas[39;00m [38;5;21;01mpd[39;00m

[0;31mImportError[0m: cannot import name 'solve_shadow_map' from 'cython' (/home/frederikwr/anaconda3/envs/WindBro/lib/python3.11/site-packages/cython.py)
ImportError: cannot import name 'solve_shadow_map' from 'cython' (/home/frederikwr/anaconda3/envs/WindBro/lib/python3.11/site-packages/cython.py)

