Traceback (most recent call last):
  File "/home/frederikwr/anaconda3/envs/WindBro/lib/python3.11/site-packages/nbclient/client.py", line 730, in _async_poll_for_reply
    msg = await ensure_async(self.kc.shell_channel.get_msg(timeout=new_timeout))
          ^^^^^^^^^^^^^^^^^^^^^^^^^^^^^^^^^^^^^^^^^^^^^^^^^^^^^^^^^^^^^^^^^^^^^^
  File "/home/frederikwr/anaconda3/envs/WindBro/lib/python3.11/site-packages/nbclient/util.py", line 96, in ensure_async
    result = await obj
             ^^^^^^^^^
  File "/home/frederikwr/anaconda3/envs/WindBro/lib/python3.11/site-packages/jupyter_client/channels.py", line 315, in get_msg
    raise Empty
_queue.Empty

During handling of the above exception, another exception occurred:

Traceback (most recent call last):
  File "/home/frederikwr/anaconda3/envs/WindBro/lib/python3.11/site-packages/jupyter_cache/executors/utils.py", line 58, in single_nb_execution
    executenb(
  File "/home/frederikwr/anaconda3/envs/WindBro/lib/python3.11/site-packages/nbclient/client.py", line 1204, in execute
    return NotebookClient(nb=nb, resources=resources, km=km, **kwargs).execute()
           ^^^^^^^^^^^^^^^^^^^^^^^^^^^^^^^^^^^^^^^^^^^^^^^^^^^^^^^^^^^^^^^^^^^^^
  File "/home/frederikwr/anaconda3/envs/WindBro/lib/python3.11/site-packages/nbclient/util.py", line 84, in wrapped
    return just_run(coro(*args, **kwargs))
           ^^^^^^^^^^^^^^^^^^^^^^^^^^^^^^^
  File "/home/frederikwr/anaconda3/envs/WindBro/lib/python3.11/site-packages/nbclient/util.py", line 62, in just_run
    return loop.run_until_complete(coro)
           ^^^^^^^^^^^^^^^^^^^^^^^^^^^^^
  File "/home/frederikwr/anaconda3/envs/WindBro/lib/python3.11/asyncio/base_events.py", line 653, in run_until_complete
    return future.result()
           ^^^^^^^^^^^^^^^
  File "/home/frederikwr/anaconda3/envs/WindBro/lib/python3.11/site-packages/nbclient/client.py", line 663, in async_execute
    await self.async_execute_cell(
  File "/home/frederikwr/anaconda3/envs/WindBro/lib/python3.11/site-packages/nbclient/client.py", line 949, in async_execute_cell
    exec_reply = await self.task_poll_for_reply
                 ^^^^^^^^^^^^^^^^^^^^^^^^^^^^^^
  File "/home/frederikwr/anaconda3/envs/WindBro/lib/python3.11/site-packages/nbclient/client.py", line 754, in _async_poll_for_reply
    await self._async_handle_timeout(timeout, cell)
  File "/home/frederikwr/anaconda3/envs/WindBro/lib/python3.11/site-packages/nbclient/client.py", line 801, in _async_handle_timeout
    raise CellTimeoutError.error_from_timeout_and_cell(
nbclient.exceptions.CellTimeoutError: A cell timed out while it was being executed, after 30 seconds.
The message was: Cell execution timed out.
Here is a preview of the cell contents:
-------------------
['def multiprocessing(func, points, sun_vec, minBound, maxBound, voxel_map, processes):', '    pool = mp.Pool(processes=processes)', '    results = []', '    ', '    for process in range(processes):']
...
['    ', '    np.savetxt("../../temp/shadow_map.txt", shadow_map)', '    return shadow_map', '', 'shadow_map = multiprocessing(solve_shadow_map.solve_shadow_map_cy, points, sun_vec, minBound, maxBound, voxel_map, 20)']
-------------------

